Workbook

Sheet Sheet1
B2: TEST CASE
B3: Version: | C3: 1.0
B4: Issue date: | C4: 46268
B6: Project Name: | C6: LD INDONESIA
B7: Project Code: | C7: LD - 2026
B10: Record of change:
B11: Effective Date | C11: Version | D11: Change location | E11: Change description | F11: Originator | G11: Reviewer/ Approver | H11: Reference
B12: 46268 | C12: 1.0 | D12: Surabaya | E12: Initial Release | F12: Zeva Lorensia N | G12: - | H12: N/A

Sheet Admin
A1: TEST CASE
A2: System Name： | B2: LD INDONESIA
A3: Module Code： | B3: LD - Admin
A4: Test requirement:
A5: Pass | B5: =COUNTIF(G:G,"Pass") -> 68 | C5: Pending | D5: =COUNTIF(G:G,"Pending") -> 0
A6: Fail | B6: =COUNTIF(G:G,"Fail") -> 5 | C6: Number of test cases | D6: =COUNTIF(A:A,"*TC*") -> 73
A8: ID | B8: Test Case Description | C8: Test Case Procedure | D8: Test Data | E8: Expected Output | F8: Test date | G8: Result | H8: Note | I8: Screenshoot
A10: 1.Login
A11: TC1 | B11: Lupa Password dengan email terdaftar | C11: 1. Buka halaman login. 2. Klik Lupa Password. 3. Masukkan email terdaftar. 4. Masukkan Password baru & Konfirmasi 5. Klik tombol Simpan Password Baru | D11: yoeladmin@gmail.com pass:12345678 | E11: 1. Sistem menerima email dan melanjutkan proses reset password. | F11: 46268 | G11: Pass
A12: TC2 | B12: Lupa Password dengan email tidak terdaftar | C12: 1. Buka halaman login. 2. Klik Lupa Password. 3. Masukkan email tidak terdaftar. 4. Masukkan Password baru & Konfirmasi 5. Klik tombol Simpan Password Baru | D12: tidakterdaftar@gmail.com pass:12345678 | E12: 1. Sistem menampilkan peringatan bahwa email tidak ditemukan 2. Proses reset password tidak berhasil dan admin masih dihalaman Atur password baru. | F12: 46268 | G12: Pass
A13: TC3 | B13: Lupa Password dengan email kosong | C13: 1. Buka halaman login. 2. Klik Lupa Password. 3. Kosongkan email. 4. Masukkan Password baru & Konfirmasi 5. Klik tombol Simpan Password Baru | D13: Email: kosong pass:12345678 | E13: 1.Sistem menampilkan validasi bahwa pastikan data reset valid . | F13: 46268 | G13: Pass
A14: TC4 | B14: Lupa Password dengan format email tidak valid | C14: 1. Buka halaman login. 2. Klik Lupa Password. 3. Masukkan email dengan format tidak valid. 4. Masukkan Password baru & Konfirmasi 5. Klik tombol Simpan Password Baru | D14: admingmail.com | E14: 1. Sistem menampilkan validasi masukkan email yang valid. | F14: 46268 | G14: Pass
A15: TC5 | B15: Membuat password kurang dari 8 karakter | C15: 1. Buka halaman login. 2. Klik Lupa Password. 3. Masukkan email terdaftar. 4. Masukkan Password baru & Konfirmasi dengan karakter kurang dari 8 5. Klik tombol Simpan Password Baru | D15: Password: 1234567 | E15: Sistem menolak password dan menampilkan validasi bahwa password minimal 8 karakter. | F15: 46268 | G15: Pass | H15: Pesan validasi baiknya diganti "password minimal 8" agar user paham | I15: Screenshot 2026-09-06 133600.png
A16: TC6 | B16: Membuat password tepat 8 karakter | C16: 1. Buka halaman login. 2. Klik Lupa Password. 3. Masukkan email terdaftar. 4. Masukkan Password baru & Konfirmasi dengan 8 karakter 5. Klik tombol Simpan Password Baru | D16: Password: 12345678 | E16: 1. Sistem menerima email dan melanjutkan proses reset password. | F16: 46268 | G16: Pass
A17: TC7 | B17: Membuat password lebih dari 8 karakter | C17: 1. Buka halaman login. 2. Klik Lupa Password. 3. Masukkan email terdaftar. 4. Masukkan Password baru & Konfirmasi dengan karakter lebih dari 8 5. Klik tombol Simpan Password Baru | D17: Password: Adminnn123 | E17: 1. Sistem menerima email dan melanjutkan proses reset password. | F17: 46268 | G17: Pass
A18: TC8 | B18: Membuat Password dengan field password kosong | C18: 1. Buka halaman login. 2. Klik Lupa Password. 3. Masukkan email terdaftar. 4. Kosongkan Password 5. Isi Konfirmasi password 6. Klik tombol Simpan Password Baru | D18: Password: kosong | E18: 1.Sistem menampilkan validasi bahwa pastikan data reset valid . | F18: 46268 | G18: Pass
A19: TC9 | B19: Membuat Password dengan field konfirmasi password kosong | C19: 1. Buka halaman login. 2. Klik Lupa Password. 3. Masukkan email terdaftar. 4. Isi Password 5. Kosongkan Konfirmasi password 6. Klik tombol Simpan Password Baru | D19: Password: Adminnn123 Konfirmasi: kosong | E19: 1.Sistem menampilkan validasi bahwa pastikan data reset valid . | F19: 46268 | G19: Pass
A20: TC10 | B20: Password dan konfirmasi password berbeda | C20: 1. Buka halaman login. 2. Klik Lupa Password. 3. Masukkan email terdaftar. 4. Masukkan password baru. 5.. Masukkan konfirmasi password yang berbeda. 6. Klik tombol Simpan Password Baru | D20: Password: Adminnn123 Konfirmasi: Adminnn345 | E20: Sistem menolak perubahan password dan menampilkan peringatan validasi bahwa pastikan data reset valid | F20: 46268 | G20: Pass
A21: TC11 | B21: Login dengan Email dan Password valid | C21: 1. Buka website LD Indonesia. 2. Pastikan halaman Landing Page berhasil ditampilkan. 3. Klik tombol Masuk. 4. Masukkan email yang valid. 5. Masukkan password yang valid. 6. Klik tombol Masuk. | D21: Email : admin@ldindonesia.test Password : password | E21: 1. Halaman Login berhasil ditampilkan. 2. Sistem menerima email dan password yang valid. 3. Sistem melakukan autentikasi pengguna. 4. Pengguna berhasil login. 5. Dashboard ditampilkan sesuai hak akses pengguna. | F21: 46268 | G21: Pass
A22: TC12 | B22: Login dengan Email dan Password tidak valid | C22: 1. Buka website LD Indonesia. 2. Pastikan halaman Landing Page berhasil ditampilkan. 3. Klik tombol Masuk. 4. Masukkan email yang tidak valid. 5. Masukkan password tidak yang valid. 6. Klik tombol Masuk. | D22: Email : admin@.test Password : admin | E22: Sistem menolak proses login. Pesan kesalahan ditampilkan "Email atau password salah." Pengguna tetap berada pada halaman Login. Kolom login tetap dapat diedit untuk mencoba kembali. | F22: 46268 | G22: Pass | H22: Kalimat peringatan tidak konsisten | I22: Screenshot 2026-09-03 151305.png
A23: TC13 | B23: Login dengan email yang tidak valid dan password yang valid | C23: 1. Buka website LD Indonesia. 2. Pastikan halaman Landing Page berhasil ditampilkan. 3. Klik tombol Masuk. 4. Masukkan email yang tidak valid. 5. Masukkan password yang valid. 6. Klik tombol Masuk. | D23: Email : admin@.test Password : password | E23: Sistem menolak proses login. Pesan kesalahan ditampilkan,"Masukkan alamat email yang valid." Pengguna tetap berada pada halaman Login. Kolom login tetap dapat diedit untuk mencoba kembali. | F23: 46268 | G23: Pass
A24: TC14 | B24: Login dengan email yang valid dan password yang tidak valid | C24: 1. Buka website LD Indonesia. 2. Pastikan halaman Landing Page berhasil ditampilkan. 3. Klik tombol Masuk. 4. Masukkan email yang valid. 5. Masukkan password yang tidak valid. 6. Klik tombol Masuk. | D24: Email : admin@ldindonesia.test Password : admin | E24: Sistem menolak proses login. Pesan kesalahan ditampilkan,"Masukkan password yang valid." Pengguna tetap berada pada halaman Login. Kolom login tetap dapat diedit untuk mencoba kembali. | F24: 46268 | G24: Fail | I24: Screenshot 2026-09-03 145116.png
A25: TC15 | B25: Login dengan email kosong | C25: 1. Buka website LD Indonesia. 2. Pastikan halaman Landing Page berhasil ditampilkan. 3. Klik tombol Masuk. 4. Kosongkan email 5. Masukkan password yang valid. 6. Klik tombol Masuk. | D25: Email : - Password : password | E25: Sistem menolak proses login. Pesan kesalahan ditampilkan,"Email wajib diisi." Pengguna tetap berada pada halaman Login. Kolom login tetap dapat diedit untuk mencoba kembali. | F25: 46268 | G25: Pass
A26: TC16 | B26: Login dengan password kosong | C26: 1. Buka website LD Indonesia. 2. Pastikan halaman Landing Page berhasil ditampilkan. 3. Klik tombol Masuk. 4. Masukkan email yang valid. 5. Kosongkan password. 6. Klik tombol Masuk. | D26: Email : admin@ldindonesia.test Password : - | E26: Sistem menolak proses login. Pesan kesalahan ditampilkan,"Password wajib diisi." Pengguna tetap berada pada halaman Login. Kolom login tetap dapat diedit untuk mencoba kembali. | F26: 46268 | G26: Pass
A27: TC17 | B27: Login dengan email dan password kosong | C27: 1. Buka website LD Indonesia. 2. Pastikan halaman Landing Page berhasil ditampilkan. 3. Klik tombol Masuk. 4. Kosongkan email. 5. Kosongkan password. 6. Klik tombol Masuk. | D27: Email : - Password : - | E27: Sistem menolak proses login. Pesan kesalahan ditampilkan,"Email dan Password wajib diisi." Pengguna tetap berada pada halaman Login. Kolom login tetap dapat diedit untuk mencoba kembali. | F27: 46268 | G27: Pass | H27: Pesan kesalahannya masi "email wajib diisi" | I27: Screenshot 2026-09-03 151951.png
A28: 2. Dashboard
A29: TC18 | B29: Dashboard | C29: 1. Login menggunakan akun Admin yang valid. | D29: Login Admin | E29: 1. Halaman Dashboard berhasil ditampilkan. 2. URL mengarah ke /dashboard. | F29: 46268 | G29: Pass
A30: TC19 | B30: Informasi Pengguna | C30: 1. Login menggunakan akun Admin yang valid. | D30: Login Admin | E30: 1. Halaman Dashboard berhasil ditampilkan. 2. Informasi pengguna ditampilkan di pojok kanan atas. 3. Nama pengguna ditampilkan dengan benar. 4. Role pengguna (Admin) ditampilkan dengan benar. | F30: 46268 | G30: Pass
A31: TC20 | B31: Card Statistik | C31: 1. Login menggunakan akun Admin yang valid. | D31: Login Admin | E31: 1. Halaman Dashboard berhasil ditampilkan. 2. Card Total Siswa ditampilkan. 3. Card Total Modul ditampilkan. 4. Card Perlu Penilaian ditampilkan. 5. Nilai pada setiap card sesuai dengan data yang tersedia. 6. Jika belum terdapat data, nilai yang ditampilkan adalah 0. | F31: 46268 | G31: Pass
A32: TC21 | B32: Ringkasan Modul | C32: 1. Login menggunakan akun Admin yang valid. | D32: Login Admin | E32: 1. Halaman Dashboard berhasil ditampilkan. 2. Ringkasan Modul ditampilkan pada Dashboard. 3. Daftar kategori modul (Materi, Simulasi Hören, Simulasi Lesen, Simulasi Schreiben, dan Simulasi Sprechen) ditampilkan. 4.Jumlah pada setiap kategori ditampilkan sesuai data yang tersedia. 5. Jika belum terdapat data, jumlah yang ditampilkan adalah 0. | F32: 46268 | G32: Pass
A33: TC22 | B33: Daftar Perlu Dinilai | C33: 1. Login menggunakan akun Admin yang valid. | D33: Login Admin | E33: 1. Halaman Dashboard berhasil ditampilkan. 2. Panel Perlu Dinilai ditampilkan pada Dashboard. 3. Jika terdapat tugas yang belum dinilai, daftar tugas ditampilkan. 4. Jika tidak terdapat tugas yang belum dinilai, sistem menampilkan pesan "Tidak ada pengerjaan yang menunggu penilaian." | F33: 46268 | G33: Pass
A34: TC23 | B34: Lihat Semua Modul | C34: 1. Login menggunakan akun Admin yang valid. 2. Klik tombol Lihat semua modul pada card ringkasan modul. | D34: Login Admin | E34: 1. Admin diarahkan ke halaman Modul Pembelajaran. 2. Halaman Modul Pembelajaran berhasil ditampilkan. | F34: 46268 | G34: Pass
A35: 3. Modul Pembelajaran
A36: TC24 | B36: Halaman Modul Pembelajaran | C36: 1. Login menggunakan akun Admin yang valid. 2. Klik menu Modul Pembelajaran. | D36: Login Admin | E36: 1. Halaman Kelola Modul berhasil ditampilkan. 2. Daftar modul ditampilkan. 3. Jika belum terdapat data, sistem menampilkan pesan "Modul belum tersedia". | F36: 46268 | G36: Pass
A37: FORM TAMBAH MODUL
A38: TC25 | B38: Tambah Modul Kategori Materi (Data Valid) | C38: 1. Login menggunakan akun Admin yang valid. 2. Klik menu Modul Pembelajaran. 3. Klik Tambah Modul 4. Isi Judul Modul. 5. Pilih Level. 6. Pilih kategori Materi. 7. Isi Deskripsi. 8. Unggah file materi. 9. Klik Selanjutnya. 10.Tambahkan soal. 11. Isi pilihan jawaban. 12. Isi penjelasan jawaban (opsional) 13. Klik Simpan Semua Soal. | D38: Judul Modul : Einführung A1 Level : A1 Kategori: Materi Deskripsi: Materi pengenalan bahasa Jerman tingkat A1 File Materi : `Materi_A1_Pengenalan.pdf` Apa arti dari "Guten Morgen"? Pilihan A :Selamat Pagi Pilihan B :Selamat Siang Pilihan C :Selamat Malam Pilihan D :Sampai Jumpa Jawaban Benar : A Penjelasan : "Guten Morgen" digunakan untuk mengucapkan selamat pagi. | E38: 1. Modul berhasil dibuat. 2. Pengguna diarahkan ke halaman Kelola modul 3. Data modul muncul dan tersimpan. | F38: 46268 | G38: Pass
A39: TC26 | B39: Tambah Modul Kategori Simulasi Hoeren (Data Valid) | C39: 1. Login menggunakan akun Admin yang valid. 2. Klik menu Modul Pembelajaran. 3. Klik Tambah Modul 4. Isi Judul Modul. 5. Pilih Level. 6. Pilih kategori Simulasi Hoeren . 7. Isi Deskripsi. 8. Klik Selanjutnya. 9.Tambahkan soal. 10. Upload Audio. 11. Isi pilihan jawaban. 12. Isi penjelasan jawaban (opsional) 13. Klik Simpan Semua Soal. | D39: Judul Modul:Begrüßung Level: A2 Kategori: Simulasi Hören Deskripsi: Simulasi latihan mendengarkan percakapan sederhana bahasa Jerman tingkat A1. Pertanyaan : Berdasarkan audio, apa yang diucapkan saat menyapa di pagi hari? Pilihan A : Guten Morgen Pilihan B : Guten Abend Pilihan C : Gute Nacht Pilihan D : Auf Wiedersehen Jawaban Benar : A Penjelasan : Pada audio terdengar ucapan "Guten Morgen" sebagai salam di pagi hari. | E39: 1. Modul berhasil dibuat. 2. Pengguna diarahkan ke halaman Kelola modul 3. Data modul muncul dan tersimpan. | F39: 46268 | G39: Fail | H39: File materi Audio keterangan "Tidak Ada" | I39: Screenshot 2026-09-03 173647.png
A40: TC27 | B40: Tambah Modul Kategori Simulasi Lesen(Data Valid) | C40: 1. Login menggunakan akun Admin yang valid. 2. Klik menu Modul Pembelajaran. 3. Klik Tambah Modul 4. Isi Judul Modul. 5. Pilih Level. 6. Pilih kategori Simulasi Lesen . 7. Isi Deskripsi. 8. Klik Selanjutnya. 9.Tambahkan soal. 11. Isi pilihan jawaban. 12. Isi penjelasan jawaban (opsional) 13. Klik Simpan Semua Soal. | D40: Judul Modul: Familie Level : B1 Kategori : Simulasi Lesen Deskripsi : Simulasi latihan membaca teks sederhana tentang keluarga. Hallo! Ich heiße Anna. Ich wohne mit meiner Familie in Berlin. Ich habe einen Bruder und eine Schwester. Wir spielen jeden Sonntag zusammen im Park. Pertanyaan : Mit wem wohnt Anna? Pilihan A : Mit ihrer Familie Pilihan B : Mit ihrer Freundin Pilihan C : Allein Pilihan D : Mit ihren Großeltern Jawaban Benar :A Penjelasan : Pada teks tertulis "Ich wohne mit meiner Familie in Berlin." | E40: 1. Modul berhasil dibuat. 2. Pengguna diarahkan ke halaman Kelola modul 3. Data modul muncul dan tersimpan. | F40: 46268 | G40: Pass
A41: TC28 | B41: Tambah Modul Kategori Simulasi Schreiben(Data Valid) | C41: 1. Login menggunakan akun Admin yang valid. 2. Klik menu Modul Pembelajaran. 3. Klik Tambah Modul 4. Isi Judul Modul. 5. Pilih Level. 6. Pilih kategori Simulasi Schreiben. 7. Isi Deskripsi. 8. Klik Selanjutnya. 9.Tambahkan soal. 12. Isi penjelasan jawaban (opsional) 13. Klik Simpan Semua Soal. | D41: Judul Modul : Perkenalan Diri Level : B2 Kategori: Simulasi Schreiben Deskripsi: Simulasi latihan menulis perkenalan diri dalam bahasa Jerman. Instruksi : Schreiben Sie eine kurze Vorstellung über sich selbst (30-50 Wörter). | E41: 1. Modul berhasil dibuat. 2. Pengguna diarahkan ke halaman Kelola modul 3. Data modul muncul dan tersimpan. | F41: 46268 | G41: Pass
A42: TC29 | B42: Tambah Modul Kategori Simulasi Sprechen (Data Valid) | C42: 1. Login menggunakan akun Admin yang valid. 2. Klik menu Modul Pembelajaran. 3. Klik Tambah Modul 4. Isi Judul Modul. 5. Pilih Level. 6. Pilih kategori Simulasi Sprechen. 7. Isi Deskripsi. 8. Klik Selanjutnya. 9.Tambahkan soal. 12. Isi penjelasan jawaban (opsional) 13. Klik Simpan Semua Soal. | D42: Judul Modul : Hobbys Level : A1 Kategori :Simulasi Sprechen Deskripsi : Simulasi latihan berbicara mengenai hobi dalam bahasa Jerman Topik Sprechen : Erzählen Sie über Ihre Hobbys. (Ceritakan tentang hobi Anda.) Sampaikan jawaban selama 1-2 menit menggunakan bahasa Jerman. | E42: 1. Modul berhasil dibuat. 2. Pengguna diarahkan ke halaman Kelola modul 3. Data modul muncul dan tersimpan. | F42: 46268 | G42: Pass
...

Sheet Siswa
A1: TEST CASE
A2: System Name： | B2: Sirasa
A3: Module Code： | B3: Sirasa - Auditor
A4: Test requirement:
A5: Pass | B5: =COUNTIF(G:G,"Pass") -> 40 | C5: Pending | D5: =COUNTIF(G:G,"Pending") -> 0
A6: Fail | B6: =COUNTIF(G:G,"Fail") -> 2 | C6: Number of test cases: | D6: =COUNTIF(A:A,"*TC*") -> 42
A8: ID | B8: Test Case Description | C8: Test Case Procedure | D8: Test Data | E8: Expected Output | F8: Test date | G8: Result | H8: Note | I8: Screenshoot
A10: 1.Login
A11: TC1 | B11: Lupa Password dengan email terdaftar | C11: 1. Buka halaman login. 2. Klik Lupa Password. 3. Masukkan email terdaftar. 4. Masukkan Password baru & Konfirmasi 5. Klik tombol Simpan Password Baru | D11: siswacoba2@gmail.com pass:12345678 | E11: 1. Sistem menerima email dan melanjutkan proses reset password. | F11: 46269 | G11: Pass
A12: TC2 | B12: Lupa Password dengan email tidak terdaftar | C12: 1. Buka halaman login. 2. Klik Lupa Password. 3. Masukkan email tidak terdaftar. 4. Masukkan Password baru & Konfirmasi 5. Klik tombol Simpan Password Baru | D12: tidakterdaftar@gmail.com pass:12345678 | E12: 1. Sistem menampilkan peringatan bahwa email tidak ditemukan 2. Proses reset password tidak berhasil dan admin masih dihalaman Atur password baru. | F12: 46269 | G12: Pass
A13: TC3 | B13: Lupa Password dengan email kosong | C13: 1. Buka halaman login. 2. Klik Lupa Password. 3. Kosongkan email. 4. Masukkan Password baru & Konfirmasi 5. Klik tombol Simpan Password Baru | D13: Email: kosong pass:12345678 | E13: 1.Sistem menampilkan validasi bahwa pastikan data reset valid . | F13: 46269 | G13: Pass
A14: TC4 | B14: Lupa Password dengan format email tidak valid | C14: 1. Buka halaman login. 2. Klik Lupa Password. 3. Masukkan email dengan format tidak valid. 4. Masukkan Password baru & Konfirmasi 5. Klik tombol Simpan Password Baru | D14: siswagmail.com | E14: 1. Sistem menampilkan validasi masukkan email yang valid. | F14: 46269 | G14: Pass
A15: TC5 | B15: Membuat password kurang dari 8 karakter | C15: 1. Buka halaman login. 2. Klik Lupa Password. 3. Masukkan email terdaftar. 4. Masukkan Password baru & Konfirmasi dengan karakter kurang dari 8 5. Klik tombol Simpan Password Baru | D15: Password: 1234567 | E15: Sistem menolak password dan menampilkan validasi bahwa password minimal 8 karakter. | F15: 46269 | G15: Pass | H15: Pesan validasi baiknya diganti "password minimal 8" agar user paham | I15: Screenshot 2026-09-06 113341.png
A16: TC6 | B16: Membuat password tepat 8 karakter | C16: 1. Buka halaman login. 2. Klik Lupa Password. 3. Masukkan email terdaftar. 4. Masukkan Password baru & Konfirmasi dengan 8 karakter 5. Klik tombol Simpan Password Baru | D16: Password: 12345678 | E16: 1. Sistem menerima email dan melanjutkan proses reset password. | F16: 46269 | G16: Pass
A17: TC7 | B17: Membuat password lebih dari 8 karakter | C17: 1. Buka halaman login. 2. Klik Lupa Password. 3. Masukkan email terdaftar. 4. Masukkan Password baru & Konfirmasi dengan karakter lebih dari 8 5. Klik tombol Simpan Password Baru | D17: Password: Siswaaa123 | E17: 1. Sistem menerima email dan melanjutkan proses reset password. | F17: 46269 | G17: Pass
A18: TC8 | B18: Membuat Password dengan field password kosong | C18: 1. Buka halaman login. 2. Klik Lupa Password. 3. Masukkan email terdaftar. 4. Kosongkan Password 5. Isi Konfirmasi password 6. Klik tombol Simpan Password Baru | D18: Password: kosong | E18: 1.Sistem menampilkan validasi bahwa pastikan data reset valid . | F18: 46269 | G18: Pass
A19: TC9 | B19: Membuat Password dengan field konfirmasi password kosong | C19: 1. Buka halaman login. 2. Klik Lupa Password. 3. Masukkan email terdaftar. 4. Isi Password 5. Kosongkan Konfirmasi password 6. Klik tombol Simpan Password Baru | D19: Password: Siswa123 Konfirmasi: kosong | E19: 1.Sistem menampilkan validasi bahwa pastikan data reset valid . | F19: 46269 | G19: Pass
A20: TC10 | B20: Password dan konfirmasi password berbeda | C20: 1. Buka halaman login. 2. Klik Lupa Password. 3. Masukkan email terdaftar. 4. Masukkan password baru. 5.. Masukkan konfirmasi password yang berbeda. 6. Klik tombol Simpan Password Baru | D20: Password: Siswa123 Konfirmasi: Siswaa345 | E20: Sistem menolak perubahan password dan menampilkan peringatan validasi bahwa pastikan data reset valid | F20: 46269 | G20: Pass
A21: TC11 | B21: Login dengan Email dan Password valid | C21: 1. Buka website LD Indonesia. 2. Pastikan halaman Landing Page berhasil ditampilkan. 3. Klik tombol Masuk. 4. Masukkan email yang valid. 5. Masukkan password yang valid. 6. Klik tombol Masuk. | D21: Email : admin@ldindonesia.test Password : password | E21: 1. Halaman Login berhasil ditampilkan. 2. Sistem menerima email dan password yang valid. 3. Sistem melakukan autentikasi pengguna. 4. Pengguna berhasil login. 5. Dashboard ditampilkan sesuai hak akses pengguna. | F21: 46269 | G21: Pass
A22: TC12 | B22: Login dengan Email dan Password tidak valid | C22: 1. Buka website LD Indonesia. 2. Pastikan halaman Landing Page berhasil ditampilkan. 3. Klik tombol Masuk. 4. Masukkan email yang tidak valid. 5. Masukkan password tidak yang valid. 6. Klik tombol Masuk. | D22: Email : siswa@.test Password : siswa | E22: Sistem menolak proses login. Pesan kesalahan ditampilkan "Email atau password salah." Pengguna tetap berada pada halaman Login. Kolom login tetap dapat diedit untuk mencoba kembali. | F22: 46269 | G22: Pass | H22: Kalimat peringatan tidak konsisten | I22: Screenshot 2026-09-06 135838.png
A23: TC13 | B23: Login dengan email yang tidak valid dan password yang valid | C23: 1. Buka website LD Indonesia. 2. Pastikan halaman Landing Page berhasil ditampilkan. 3. Klik tombol Masuk. 4. Masukkan email yang tidak valid. 5. Masukkan password yang valid. 6. Klik tombol Masuk. | D23: Email : admin@.test Password : password | E23: Sistem menolak proses login. Pesan kesalahan ditampilkan,"Masukkan alamat email yang valid." Pengguna tetap berada pada halaman Login. Kolom login tetap dapat diedit untuk mencoba kembali. | F23: 46269 | G23: Pass
A24: TC14 | B24: Login dengan email yang valid dan password yang tidak valid | C24: 1. Buka website LD Indonesia. 2. Pastikan halaman Landing Page berhasil ditampilkan. 3. Klik tombol Masuk. 4. Masukkan email yang valid. 5. Masukkan password yang tidak valid. 6. Klik tombol Masuk. | D24: Email : admin@ldindonesia.test Password : admin | E24: Sistem menolak proses login. Pesan kesalahan ditampilkan,"Masukkan password yang valid." Pengguna tetap berada pada halaman Login. Kolom login tetap dapat diedit untuk mencoba kembali. | F24: 46269 | G24: Pass
A25: TC15 | B25: Login dengan email kosong | C25: 1. Buka website LD Indonesia. 2. Pastikan halaman Landing Page berhasil ditampilkan. 3. Klik tombol Masuk. 4. Kosongkan email 5. Masukkan password yang valid. 6. Klik tombol Masuk. | D25: Email : - Password : password | E25: Sistem menolak proses login. Pesan kesalahan ditampilkan,"Email wajib diisi." Pengguna tetap berada pada halaman Login. Kolom login tetap dapat diedit untuk mencoba kembali. | F25: 46269 | G25: Pass
A26: TC16 | B26: Login dengan password kosong | C26: 1. Buka website LD Indonesia. 2. Pastikan halaman Landing Page berhasil ditampilkan. 3. Klik tombol Masuk. 4. Masukkan email yang valid. 5. Kosongkan password. 6. Klik tombol Masuk. | D26: Email : admin@ldindonesia.test Password : - | E26: Sistem menolak proses login. Pesan kesalahan ditampilkan,"Password wajib diisi." Pengguna tetap berada pada halaman Login. Kolom login tetap dapat diedit untuk mencoba kembali. | F26: 46269 | G26: Pass
A27: TC17 | B27: Login dengan email dan password kosong | C27: 1. Buka website LD Indonesia. 2. Pastikan halaman Landing Page berhasil ditampilkan. 3. Klik tombol Masuk. 4. Kosongkan email. 5. Kosongkan password. 6. Klik tombol Masuk. | D27: Email : - Password : - | E27: Sistem menolak proses login. Pesan kesalahan ditampilkan,"Email dan Password wajib diisi." Pengguna tetap berada pada halaman Login. Kolom login tetap dapat diedit untuk mencoba kembali. | F27: 46269 | G27: Pass | H27: Pesan kesalahannya masi "email wajib diisi" | I27: Screenshot 2026-09-06 135838.png
A28: 2. Dashboard
A29: TC18 | B29: Dashboard | C29: 1. Login menggunakan akun Siswa yang terdaftar. | D29: Login Siswa | E29: 1. Halaman Dashboard berhasil ditampilkan. 2. URL mengarah ke /dashboard. | F29: 46269 | G29: Pass
A30: TC19 | B30: Informasi Pengguna | C30: 1. Login menggunakan akun Siswa yang Terdaftar. | D30: Login Siswa | E30: 1. Halaman Dashboard berhasil ditampilkan. 2. Informasi pengguna ditampilkan di pojok kanan atas. 3. Nama pengguna ditampilkan dengan benar. 4. Role pengguna (Siswa) ditampilkan dengan benar. | F30: 46269 | G30: Pass
A31: TC20 | B31: Lihat Semua Modul | C31: 1. Login menggunakan akun Siswa yang Terdaftar. 2. Klik tombol Lihat semua modul pada card modul yang perlu dikerjakan. | D31: Login Siswa | E31: 1. Siswa diarahkan ke halaman Modul Pembelajaran. 2. Halaman Modul Pembelajaran berhasil ditampilkan. | F31: 46269 | G31: Pass
A32: TC21 | B32: Aktivitas terakhir | C32: 1. Login menggunakan akun Siswa yang Terdaftar. 2. Klik tombol Lihat semua hasill pada card aktivitas terakhir. | D32: Login Siswa | E32: 1. Siswa diarahkan ke halaman performa siswa . 2. Halaman Performa siswa berhasil ditampilkan. | F32: 46269 | G32: Pass
A33: 3. Modul Pembelajaran
A34: TC22 | B34: Halaman Modul Pembelajaran | C34: 1. Login menggunakan akun Siswa yang Terdaftar. 2. Klik menu Modul Pembelajaran. | D34: siswacoba1@gmail.com pass:12345678 | E34: 1. Halaman Kelola Modul berhasil ditampilkan. 2. Daftar modul ditampilkan. 3. Jika belum terdapat data, sistem menampilkan pesan "Modul belum tersedia". | F34: 46269 | G34: Fail | H34: Untuk siswa baru dan ada modul pembelajaran. Didashboard belum dikerjakan, Namun di menu modul Pembelajaran modul tersebut sudah selesai, dan tidak bisa dilihat Untuk Siswa Baru dan blm ada modul pembelajaran. Didashboard tulisannya " semua modul sudah dikerjakan" | I34: Screenshot 2026-09-06 112314.png Screenshot 2026-09-06 112309.png
A35: TC23 | B35: Pencarian Modul | C35: 1. Login menggunakan akun Siswa yang Terdaftar. 2. Klik menu Modul Pembelajaran. 3. Masukkan kata kunci pada kolom pencarian. 4. Klik tombol Cari. | D35: Nama Modul KONJUGASI | E35: 1. Sistem menampilkan modul yang sesuai dengan kata kunci | F35: 46269 | G35: Pass
A36: TC24 | B36: Pencarian Modul Tidak Ditemukan | C36: 1. Login menggunakan akun Siswa yang Terdaftar. 2. Klik menu Modul Pembelajaran. 3. Masukkan kata kunci pada kolom pencarian. 4. Klik tombol Cari. | D36: Nama Modul ABCXYZ | E36: 1. Sistem menampilkan bahwa data tidak ditemukan. | F36: 46269 | G36: Pass
A37: TC25 | B37: Filter Level | C37: 1. Login menggunakan akun Siswa yang Terdaftar. 2. Klik menu Modul Pembelajaran. 3. Pilih Level. | D37: Level A1 | E37: 1. Sistem hanya menampilkan modul Level A1. | F37: 46269 | G37: Pass
A38: TC26 | B38: Filter Kategori | C38: 1. Login menggunakan akun Siswa yang Terdaftar. 2. Klik menu Modul Pembelajaran. 3 Pilih kategori. | D38: Kategori Materi | E38: 1. Sistem hanya menampilkan modul kategori Materi. | F38: 46269 | G38: Pass
A39: TC27 | B39: Mengerjakan Modul Pembelajaran | C39: 1. Login menggunakan akun Siswa yang Terdaftar. 2. Klik menu Modul Pembelajaran. 3. Pilih salah satu modul. 4. Klik tombol Mulai. | D39: Modul KONJUGASI | E39: 1. Sistem membuka halaman modul. 2. Sistem menampilkan materi pembelajaran. 3. Sistem menampilkan daftar soal. 4. Sistem menampilkan nomor soal. 5. Sistem menampilkan pilihan jawaban. | F39: 46269 | G39: Pass
A40: TC28 | B40: Menjawab Soal | C40: 1. Login menggunakan akun Siswa yang Terdaftar. 2. Klik menu Modul Pembelajaran. 3. Pilih salah satu modul. 4. Klik tombol Mulai. 5. Klik selanjutnya untuk ke soal 6. Jawab soal. | D40: Jawaban Opsi B | E40: 1. Jawaban tersimpan. 2. Nomor soal berubah menjadi Sudah Dijawab. | F40: 46269 | G40: Pass
A41: TC29 | B41: Berpindah Nomor Soal | C41: 1. Login menggunakan akun Siswa yang Terdaftar. 2. Klik menu Modul Pembelajaran. 3. Pilih salah satu modul. 4. Klik tombol Mulai. 5. Klik selanjutnya untuk ke soal 6. Klik nomor soal lain. | D41: Soal no 1 | E41: 1. Sistem menampilkan soal yang dipilih. | F41: 46269 | G41: Pass
A42: TC30 | B42: Tombol Selanjutnya | C42: 1. Login menggunakan akun Siswa yang Terdaftar. 2. Klik menu Modul Pembelajaran. 3. Pilih salah satu modul. 4. Klik tombol Mulai. 5. Klik selanjutnya untuk ke soal 6. Jawab soal. 7. Klik tombol Selanjutnya. | D42: Soal no 1 | E42: 1. Sistem menampilkan soal Selanjutnya. | F42: 46269 | G42: Pass
...

Sheet Tutor
A1: TEST CASE
A2: System Name： | B2: LD INDONESIA
A3: Module Code： | B3: LD - Admin
A4: Test requirement:
A5: Pass | B5: =COUNTIF(G:G,"Pass") -> 51 | C5: Pending | D5: =COUNTIF(G:G,"Pending") -> 0
A6: Fail | B6: =COUNTIF(G:G,"Fail") -> 5 | C6: Number of test cases | D6: =COUNTIF(A:A,"*TC*") -> 56
A8: ID | B8: Test Case Description | C8: Test Case Procedure | D8: Test Data | E8: Expected Output | F8: Test date | G8: Result | H8: Note | I8: Screenshoot
A10: 1.Login
A11: TC1 | B11: Lupa Password dengan email terdaftar | C11: 1. Buka halaman login. 2. Klik Lupa Password. 3. Masukkan email terdaftar. 4. Masukkan Password baru & Konfirmasi 5. Klik tombol Simpan Password Baru | D11: yoeltutor@gmail.com pass:12345678 | E11: 1. Sistem menerima email dan melanjutkan proses reset password. | F11: 46270 | G11: Pass
A12: TC2 | B12: Lupa Password dengan email tidak terdaftar | C12: 1. Buka halaman login. 2. Klik Lupa Password. 3. Masukkan email tidak terdaftar. 4. Masukkan Password baru & Konfirmasi 5. Klik tombol Simpan Password Baru | D12: tidakterdaftar@gmail.com pass:12345678 | E12: 1. Sistem menampilkan peringatan bahwa email tidak ditemukan 2. Proses reset password tidak berhasil dan admin masih dihalaman Atur password baru. | F12: 46270 | G12: Pass
A13: TC3 | B13: Lupa Password dengan email kosong | C13: 1. Buka halaman login. 2. Klik Lupa Password. 3. Kosongkan email. 4. Masukkan Password baru & Konfirmasi 5. Klik tombol Simpan Password Baru | D13: Email: kosong pass:12345678 | E13: 1.Sistem menampilkan validasi bahwa pastikan data reset valid . | F13: 46270 | G13: Pass
A14: TC4 | B14: Lupa Password dengan format email tidak valid | C14: 1. Buka halaman login. 2. Klik Lupa Password. 3. Masukkan email dengan format tidak valid. 4. Masukkan Password baru & Konfirmasi 5. Klik tombol Simpan Password Baru | D14: tutorgmail.com | E14: 1. Sistem menampilkan validasi masukkan email yang valid. | F14: 46270 | G14: Pass
A15: TC5 | B15: Membuat password kurang dari 8 karakter | C15: 1. Buka halaman login. 2. Klik Lupa Password. 3. Masukkan email terdaftar. 4. Masukkan Password baru & Konfirmasi dengan karakter kurang dari 8 5. Klik tombol Simpan Password Baru | D15: Password: 1234567 | E15: Sistem menolak password dan menampilkan validasi bahwa password minimal 8 karakter. | F15: 46270 | G15: Pass | H15: Pesan validasi baiknya diganti "password minimal 8" agar user paham
A16: TC6 | B16: Membuat password tepat 8 karakter | C16: 1. Buka halaman login. 2. Klik Lupa Password. 3. Masukkan email terdaftar. 4. Masukkan Password baru & Konfirmasi dengan 8 karakter 5. Klik tombol Simpan Password Baru | D16: Password: 12345678 | E16: 1. Sistem menerima email dan melanjutkan proses reset password. | F16: 46270 | G16: Pass
A17: TC7 | B17: Membuat password lebih dari 8 karakter | C17: 1. Buka halaman login. 2. Klik Lupa Password. 3. Masukkan email terdaftar. 4. Masukkan Password baru & Konfirmasi dengan karakter lebih dari 8 5. Klik tombol Simpan Password Baru | D17: Password: Adminnn123 | E17: 1. Sistem menerima email dan melanjutkan proses reset password. | F17: 46270 | G17: Pass
A18: TC8 | B18: Membuat Password dengan field password kosong | C18: 1. Buka halaman login. 2. Klik Lupa Password. 3. Masukkan email terdaftar. 4. Kosongkan Password 5. Isi Konfirmasi password 6. Klik tombol Simpan Password Baru | D18: Password: kosong | E18: 1.Sistem menampilkan validasi bahwa pastikan data reset valid . | F18: 46270 | G18: Pass
A19: TC9 | B19: Membuat Password dengan field konfirmasi password kosong | C19: 1. Buka halaman login. 2. Klik Lupa Password. 3. Masukkan email terdaftar. 4. Isi Password 5. Kosongkan Konfirmasi password 6. Klik tombol Simpan Password Baru | D19: Password: Adminnn123 Konfirmasi: kosong | E19: 1.Sistem menampilkan validasi bahwa pastikan data reset valid . | F19: 46270 | G19: Pass
A20: TC10 | B20: Password dan konfirmasi password berbeda | C20: 1. Buka halaman login. 2. Klik Lupa Password. 3. Masukkan email terdaftar. 4. Masukkan password baru. 5.. Masukkan konfirmasi password yang berbeda. 6. Klik tombol Simpan Password Baru | D20: Password: Adminnn123 Konfirmasi: Adminnn345 | E20: Sistem menolak perubahan password dan menampilkan peringatan validasi bahwa pastikan data reset valid | F20: 46270 | G20: Pass
A21: TC11 | B21: Login dengan Email dan Password valid | C21: 1. Buka website LD Indonesia. 2. Pastikan halaman Landing Page berhasil ditampilkan. 3. Klik tombol Masuk. 4. Masukkan email yang valid. 5. Masukkan password yang valid. 6. Klik tombol Masuk. | D21: Email : yoeltutor@gmail.com Password : 12345678 | E21: 1. Halaman Login berhasil ditampilkan. 2. Sistem menerima email dan password yang valid. 3. Sistem melakukan autentikasi pengguna. 4. Pengguna berhasil login. 5. Dashboard ditampilkan sesuai hak akses pengguna. | F21: 46270 | G21: Pass
A22: TC12 | B22: Login dengan Email dan Password tidak valid | C22: 1. Buka website LD Indonesia. 2. Pastikan halaman Landing Page berhasil ditampilkan. 3. Klik tombol Masuk. 4. Masukkan email yang tidak valid. 5. Masukkan password tidak yang valid. 6. Klik tombol Masuk. | D22: Email : tutor@.test Password : tutor | E22: Sistem menolak proses login. Pesan kesalahan ditampilkan "Email atau password salah." Pengguna tetap berada pada halaman Login. Kolom login tetap dapat diedit untuk mencoba kembali. | F22: 46270 | G22: Pass | H22: Kalimat peringatan tidak konsisten pakai yang "email atau password salah"
A23: TC13 | B23: Login dengan email yang tidak valid dan password yang valid | C23: 1. Buka website LD Indonesia. 2. Pastikan halaman Landing Page berhasil ditampilkan. 3. Klik tombol Masuk. 4. Masukkan email yang tidak valid. 5. Masukkan password yang valid. 6. Klik tombol Masuk. | D23: Email : tutor@.test Password : 12345678 | E23: Sistem menolak proses login. Pesan kesalahan ditampilkan,"Masukkan alamat email yang valid." Pengguna tetap berada pada halaman Login. Kolom login tetap dapat diedit untuk mencoba kembali. | F23: 46270 | G23: Pass
A24: TC14 | B24: Login dengan email yang valid dan password yang tidak valid | C24: 1. Buka website LD Indonesia. 2. Pastikan halaman Landing Page berhasil ditampilkan. 3. Klik tombol Masuk. 4. Masukkan email yang valid. 5. Masukkan password yang tidak valid. 6. Klik tombol Masuk. | D24: Email : yoeltutor@gmail.com Password : tutor | E24: Sistem menolak proses login. Pesan kesalahan ditampilkan,"Masukkan password yang valid." Pengguna tetap berada pada halaman Login. Kolom login tetap dapat diedit untuk mencoba kembali. | F24: 46270 | G24: Pass
A25: TC15 | B25: Login dengan email kosong | C25: 1. Buka website LD Indonesia. 2. Pastikan halaman Landing Page berhasil ditampilkan. 3. Klik tombol Masuk. 4. Kosongkan email 5. Masukkan password yang valid. 6. Klik tombol Masuk. | D25: Email : - Password : password | E25: Sistem menolak proses login. Pesan kesalahan ditampilkan,"Email wajib diisi." Pengguna tetap berada pada halaman Login. Kolom login tetap dapat diedit untuk mencoba kembali. | F25: 46270 | G25: Pass
A26: TC16 | B26: Login dengan password kosong | C26: 1. Buka website LD Indonesia. 2. Pastikan halaman Landing Page berhasil ditampilkan. 3. Klik tombol Masuk. 4. Masukkan email yang valid. 5. Kosongkan password. 6. Klik tombol Masuk. | D26: Email : admin@ldindonesia.test Password : - | E26: Sistem menolak proses login. Pesan kesalahan ditampilkan,"Password wajib diisi." Pengguna tetap berada pada halaman Login. Kolom login tetap dapat diedit untuk mencoba kembali. | F26: 46270 | G26: Pass
A27: TC17 | B27: Login dengan email dan password kosong | C27: 1. Buka website LD Indonesia. 2. Pastikan halaman Landing Page berhasil ditampilkan. 3. Klik tombol Masuk. 4. Kosongkan email. 5. Kosongkan password. 6. Klik tombol Masuk. | D27: Email : - Password : - | E27: Sistem menolak proses login. Pesan kesalahan ditampilkan,"Email dan Password wajib diisi." Pengguna tetap berada pada halaman Login. Kolom login tetap dapat diedit untuk mencoba kembali. | F27: 46270 | G27: Pass | H27: Pesan kesalahannya masi "email wajib diisi"
A28: 2. Dashboard
A29: TC18 | B29: Dashboard | C29: 1. Login menggunakan akun Admin yang valid. | D29: Login Admin | E29: 1. Halaman Dashboard berhasil ditampilkan. 2. URL mengarah ke /dashboard. | F29: 46270 | G29: Pass
A30: TC19 | B30: Informasi Pengguna | C30: 1. Login menggunakan akun Admin yang valid. | D30: Login Admin | E30: 1. Halaman Dashboard berhasil ditampilkan. 2. Informasi pengguna ditampilkan di pojok kanan atas. 3. Nama pengguna ditampilkan dengan benar. 4. Role pengguna (Admin) ditampilkan dengan benar. | F30: 46270 | G30: Pass
A31: TC20 | B31: Card Statistik | C31: 1. Login menggunakan akun Admin yang valid. | D31: Login Admin | E31: 1. Halaman Dashboard berhasil ditampilkan. 2. Card Total Siswa ditampilkan. 3. Card Total Modul ditampilkan. 4. Card Perlu Penilaian ditampilkan. 5. Nilai pada setiap card sesuai dengan data yang tersedia. 6. Jika belum terdapat data, nilai yang ditampilkan adalah 0. | F31: 46270 | G31: Pass
A32: TC21 | B32: Ringkasan Modul | C32: 1. Login menggunakan akun Admin yang valid. | D32: Login Admin | E32: 1. Halaman Dashboard berhasil ditampilkan. 2. Ringkasan Modul ditampilkan pada Dashboard. 3. Daftar kategori modul (Materi, Simulasi Hören, Simulasi Lesen, Simulasi Schreiben, dan Simulasi Sprechen) ditampilkan. 4.Jumlah pada setiap kategori ditampilkan sesuai data yang tersedia. 5. Jika belum terdapat data, jumlah yang ditampilkan adalah 0. | F32: 46270 | G32: Pass
A33: TC22 | B33: Daftar Perlu Dinilai | C33: 1. Login menggunakan akun Admin yang valid. | D33: Login Admin | E33: 1. Halaman Dashboard berhasil ditampilkan. 2. Panel Perlu Dinilai ditampilkan pada Dashboard. 3. Jika terdapat tugas yang belum dinilai, daftar tugas ditampilkan. 4. Jika tidak terdapat tugas yang belum dinilai, sistem menampilkan pesan "Tidak ada pengerjaan yang menunggu penilaian." | F33: 46270 | G33: Pass
A34: TC23 | B34: Lihat Semua Modul | C34: 1. Login menggunakan akun Admin yang valid. 2. Klik tombol Lihat semua modul pada card ringkasan modul. | D34: Login Admin | E34: 1. Admin diarahkan ke halaman Modul Pembelajaran. 2. Halaman Modul Pembelajaran berhasil ditampilkan. | F34: 46270 | G34: Pass
A35: 3. Modul Pembelajaran
A36: TC24 | B36: Halaman Modul Pembelajaran | C36: 1. Login menggunakan akun Admin yang valid. 2. Klik menu Modul Pembelajaran. | D36: Login Admin | E36: 1. Halaman Kelola Modul berhasil ditampilkan. 2. Daftar modul ditampilkan. 3. Jika belum terdapat data, sistem menampilkan pesan "Modul belum tersedia". | F36: 46270 | G36: Pass
A37: FORM TAMBAH MODUL
A38: TC25 | B38: Tambah Modul Kategori Materi (Data Valid) | C38: 1. Login menggunakan akun Admin yang valid. 2. Klik menu Modul Pembelajaran. 3. Klik Tambah Modul 4. Isi Judul Modul. 5. Pilih Level. 6. Pilih kategori Materi. 7. Isi Deskripsi. 8. Unggah file materi. 9. Klik Selanjutnya. 10.Tambahkan soal. 11. Isi pilihan jawaban. 12. Isi penjelasan jawaban (opsional) 13. Klik Simpan Semua Soal. | D38: Judul Modul : Einführung A1 Level : A1 Kategori: Materi Deskripsi: Materi pengenalan bahasa Jerman tingkat A1 File Materi : `Materi_A1_Pengenalan.pdf` Apa arti dari "Guten Morgen"? Pilihan A :Selamat Pagi Pilihan B :Selamat Siang Pilihan C :Selamat Malam Pilihan D :Sampai Jumpa Jawaban Benar : A Penjelasan : "Guten Morgen" digunakan untuk mengucapkan selamat pagi. | E38: 1. Modul berhasil dibuat. 2. Pengguna diarahkan ke halaman Kelola modul 3. Data modul muncul dan tersimpan. | F38: 46270 | G38: Pass
A39: TC26 | B39: Tambah Modul Kategori Simulasi Hoeren (Data Valid) | C39: 1. Login menggunakan akun Admin yang valid. 2. Klik menu Modul Pembelajaran. 3. Klik Tambah Modul 4. Isi Judul Modul. 5. Pilih Level. 6. Pilih kategori Simulasi Hoeren . 7. Isi Deskripsi. 8. Klik Selanjutnya. 9.Tambahkan soal. 10. Upload Audio. 11. Isi pilihan jawaban. 12. Isi penjelasan jawaban (opsional) 13. Klik Simpan Semua Soal. | D39: Judul Modul:Begrüßung Level: A2 Kategori: Simulasi Hören Deskripsi: Simulasi latihan mendengarkan percakapan sederhana bahasa Jerman tingkat A1. Pertanyaan : Berdasarkan audio, apa yang diucapkan saat menyapa di pagi hari? Pilihan A : Guten Morgen Pilihan B : Guten Abend Pilihan C : Gute Nacht Pilihan D : Auf Wiedersehen Jawaban Benar : A Penjelasan : Pada audio terdengar ucapan "Guten Morgen" sebagai salam di pagi hari. | E39: 1. Modul berhasil dibuat. 2. Pengguna diarahkan ke halaman Kelola modul 3. Data modul muncul dan tersimpan. | F39: 46270 | G39: Fail | H39: File materi Audio keterangan "Tidak Ada"
A40: TC27 | B40: Tambah Modul Kategori Simulasi Lesen(Data Valid) | C40: 1. Login menggunakan akun Admin yang valid. 2. Klik menu Modul Pembelajaran. 3. Klik Tambah Modul 4. Isi Judul Modul. 5. Pilih Level. 6. Pilih kategori Simulasi Lesen . 7. Isi Deskripsi. 8. Klik Selanjutnya. 9.Tambahkan soal. 11. Isi pilihan jawaban. 12. Isi penjelasan jawaban (opsional) 13. Klik Simpan Semua Soal. | D40: Judul Modul: Familie Level : B1 Kategori : Simulasi Lesen Deskripsi : Simulasi latihan membaca teks sederhana tentang keluarga. Hallo! Ich heiße Anna. Ich wohne mit meiner Familie in Berlin. Ich habe einen Bruder und eine Schwester. Wir spielen jeden Sonntag zusammen im Park. Pertanyaan : Mit wem wohnt Anna? Pilihan A : Mit ihrer Familie Pilihan B : Mit ihrer Freundin Pilihan C : Allein Pilihan D : Mit ihren Großeltern Jawaban Benar :A Penjelasan : Pada teks tertulis "Ich wohne mit meiner Familie in Berlin." | E40: 1. Modul berhasil dibuat. 2. Pengguna diarahkan ke halaman Kelola modul 3. Data modul muncul dan tersimpan. | F40: 46270 | G40: Pass
A41: TC28 | B41: Tambah Modul Kategori Simulasi Schreiben(Data Valid) | C41: 1. Login menggunakan akun Admin yang valid. 2. Klik menu Modul Pembelajaran. 3. Klik Tambah Modul 4. Isi Judul Modul. 5. Pilih Level. 6. Pilih kategori Simulasi Schreiben. 7. Isi Deskripsi. 8. Klik Selanjutnya. 9.Tambahkan soal. 12. Isi penjelasan jawaban (opsional) 13. Klik Simpan Semua Soal. | D41: Judul Modul : Perkenalan Diri Level : B2 Kategori: Simulasi Schreiben Deskripsi: Simulasi latihan menulis perkenalan diri dalam bahasa Jerman. Instruksi : Schreiben Sie eine kurze Vorstellung über sich selbst (30-50 Wörter). | E41: 1. Modul berhasil dibuat. 2. Pengguna diarahkan ke halaman Kelola modul 3. Data modul muncul dan tersimpan. | F41: 46270 | G41: Pass
A42: TC29 | B42: Tambah Modul Kategori Simulasi Sprechen (Data Valid) | C42: 1. Login menggunakan akun Admin yang valid. 2. Klik menu Modul Pembelajaran. 3. Klik Tambah Modul 4. Isi Judul Modul. 5. Pilih Level. 6. Pilih kategori Simulasi Sprechen. 7. Isi Deskripsi. 8. Klik Selanjutnya. 9.Tambahkan soal. 12. Isi penjelasan jawaban (opsional) 13. Klik Simpan Semua Soal. | D42: Judul Modul : Hobbys Level : A1 Kategori :Simulasi Sprechen Deskripsi : Simulasi latihan berbicara mengenai hobi dalam bahasa Jerman Topik Sprechen : Erzählen Sie über Ihre Hobbys. (Ceritakan tentang hobi Anda.) Sampaikan jawaban selama 1-2 menit menggunakan bahasa Jerman. | E42: 1. Modul berhasil dibuat. 2. Pengguna diarahkan ke halaman Kelola modul 3. Data modul muncul dan tersimpan. | F42: 46270 | G42: Pass
...

Sheet Test Report
A1: TEST REPORT LD INDONESIA
A3: Note: | B3: LD- Admin
A4: Date | B4: 46271
A6: No | B6: Module code | C6: Pass | D6: Fail | E6: Pending | F6: Number of test cases
A7: 1 | B7: LD- Admin | C7: =Admin!B5 -> 68 | D7: =Admin!B6 -> 5 | E7: =Admin!D5 -> 0 | F7: =Admin!D6 -> 73
B9: Sub total | C9: =C7 -> 68 | D9: =D7 -> 5 | E9: =E7 -> 0 | F9: =C9+D9+E9 -> 73
A12: Note: | B12: LD- Siswa
A13: Date | B13: 46271
A15: No | B15: Module code | C15: Pass | D15: Fail | E15: Pending | F15: Number of test cases
A16: 1 | B16: LD- Siswa | C16: =Siswa!B5 -> 40 | D16: =Siswa!B6 -> 2 | E16: =Siswa!D5 -> 0 | F16: =Siswa!D6 -> 42
B18: Sub total | C18: =C16 -> 40 | D18: =D16 -> 2 | E18: =E16 -> 0 | F18: =C18+D18+E18 -> 42
A21: Note: | B21: LD- Tutor
A22: Date | B22: 46001
A24: No | B24: Module code | C24: Pass | D24: Fail | E24: Pending | F24: Number of test cases
A25: 1 | B25: LD- Tutor | C25: =Tutor!B5 -> 51 | D25: =Tutor!B6 -> 5 | E25: =Tutor!D5 -> 0 | F25: =Tutor!D6 -> 56
B27: Sub total | C27: =C25 -> 51 | D27: =D25 -> 5 | E27: =E25 -> 0 | F27: =C27+D27+E27 -> 56
A31: No | B31: Module code | C31: Pass | D31: Fail | E31: Pending | F31: Number of test cases
A32: 1 | B32: =B7 -> LD- Admin | C32: =C9 -> 68 | D32: =D9 -> 5 | E32: =E9 -> 0 | F32: =F9 -> 73
A33: 2 | B33: =B16 -> LD- Siswa | C33: =C18 -> 40 | D33: =D18 -> 2 | E33: =E18 -> 0 | F33: =F18 -> 42
A34: 3 | B34: =B25 -> LD- Tutor | C34: =C27 -> 51 | D34: =D27 -> 5 | E34: =E27 -> 0 | F34: =F27 -> 56
B35: Sub total | C35: =SUM(C32:C34) -> 159 | D35: =SUM(D32:D34) -> 12 | E35: =SUM(E32:E34) -> 0 | F35: =SUM(F32:F34) -> 171
A37: Test coverage | C37: =(C35+D35)*100/F35 -> 100 | D37: %
A38: Test successful coverage | C38: =C35*100/F35 -> 92.982456 | D38: %
